# Promise 对象

## 1. Promise 对象基本概念

1. `Promise` 是异步编程的一种解决方案，比传统的解决方案(回调函数和事件)更合理和更强大(解决回调地狱问题)。`Promise`像是一个容器，一个异步管理容器。内置有一个记录状态值，一经改变就无法回退。从语法上说 `Promise` 是一个对象，从它可以获取异步操作的消息。

- `Promise`有三种状态：` pending(进行中)`，`fulfilled(已成功)`，`rejected(已失败)`。

- 只有异步操作的结果，可以决定当前是哪一种状态，任何其他操作都无法改变这个状态。`Promise`对象的状态改变，只有两种可能：从`pending`变为`fulfilled`和从`pending`变为`rejected`，一旦状态改变，就不会再变。

2. `Promise` 优缺点

- 优点：`Promise`对象可以将异步操作以同步操作的流程表达出来，避免了层层嵌套的回调函数
  (回调地狱)。`Promise`对象提供统一的接口，使得控制异步操作更加容易。
- 缺点：`Promise`无法取消，一旦新建它就会立即执行。如果不设置回调函数，Promise 内部抛出的错误，不会
  反应到外部。当处于`pending`状态时，无法得知目前进展到哪一个阶段。

## 2. Promise 基本使用

1. `Promise`对象是一个构造函数用来生成`Promise`实例。`Promise`构造函数接受一个函数作为参数，该函数由两个函数作为参数，分别是`resolve`和`reject`。

- `resolve`函数的作用是将`Promise`对象的状态从`pending`变为`fulfilled`，在异步操作成功时调用，并将异步操作的结果作为参数传递出去。
- `reject`函数的作用是将`Promise`对象的状态从`pending`变为`rejected`，在异步操作失败时调用并将异步操作报出的错误作为参数传递出去。
- `Promise` 新建后立即执行，`then`方法指定的回调函数，将在当前脚本所有同步任务执行完才会执行。

```js
const promise = new Promise(function (resolve, reject) {
  // ... some code
  console.log('Promise')
  if (true /* 异步操作成功 */) {
    resolve('成功')
  } else {
    reject('失败')
  }
}).then(function (val) {
  console.log('resolved')
  console.log(val)
})
console.log('Hello')
// Promise Hello  resolved 成功
```

## 3.Promise 常用方法

### Promise.prototype.then()

1. `Promise` 实例上可以使用`then` 方法，可以接受两个回调函数作为参数。这两个函数都是可选的，不一定要提供。它们都接受 `Promise` 对象传出的值作为参数。
2. `then`方法如果只有一个回调函数作为参数，那么它这个回调函数参数便是`Permise`对象在`fulfilled` 状态时执行的回调函数。
3. `then`方法如果有两个回调函数参数，第一个回调函数是 `Promise` 对象的状态变为 `fulfilled` 时调用，第二个回调函数是 `Promise` 对象的状态变为 `rejected` 时调用。

```js
const promise = new Promise((resolve, reject) => {
  if ( Math..random() > 0.5 ){
    resolve('成功')
  } else {
    reject('失败')
  }
}).then((val) => {
 // 状态为 fulfilled 时执行
}, (val) => {
 // 状态为 rejected 时执行
})
```

4. `then`方法返回的是一个新的`Promise`实例，因此可以采用链式写法，即`then`方法后面再调用另一个`then`方法。`then`方法里回调函数完成以后，会将返回值作
   为后一个`then`方法的回调函数的参数传入。

```js
const promise = new Promise((resolve, reject) => {
  resolve('hello')
})
  .then(val => {
    console.log(val) // hello
    return 'world'
  })
  .then(val => {
    console.log(val) // world
  })
  .then(val => {
    console.log(val) // undefined
  })
```

### Promise.prototype.catch()

1. `catch`方法的回调函数等同与`then`方法的第二个回调函数。`Promise.prototype.catch`方法是`.then(null, rejection)`的别名，用于指定发生错误时的回调函数。
2. 如果`then`方法的回调函数在运行中抛出错误，也会被`catch`方法捕获。

```js
const p = new Promise((resolve, reject) => {
  throw new Error('test')
})
p.then(val => console.log('fulfilled:', val)).catch(err =>
  console.log('rejected:', err)
)
// 等同于
p.then(val => console.log('fulfilled:', val)).then(null, err =>
  console.log('rejected:', err)
)
```

### Promise.prototype.resolve()

1. 方法会放回一个`fulfilled`状态的`Promise`实例。添加参数后可以在后面用`then()`取到这个传参。

- 参数可以是一个`Promise`实例。
- 参数不是具有`then`方法的对象，或根本就不是对象。
- 可以不带有任何参数

```js
const p1 = Promise.resolve('js')
// 相当于
const p2 = new Promise((resolve, reject) => {
  resolve('js')
})

p1.than(res => {
  console.log(res) // 'js'
})

p2.than(res => {
  console.log(res) // 'js'
})
```

### Promise.prototype.reject()

1. 方法返回一个新的状态为`rejected`的 `Promise` 实例，参数与上面`resolve()`方法差不多。该方法会原封不动地作为`reject`的参数，变成后续方法的参数。

```js
var p1 = Promise.reject('error')
// 等价于
var p2 = new Promise((resolve, reject) => {
  reject('error')
})
```

### Promise.prototype.all()

5. 方法用于将多个`Promise`实例，包装成一个新的`Promise`实例。参数为一个数组，数组里的元素为`Promise`实例。

- 当数组里所有的实例都是`fulfilled`状态时，新的`Promise`实例才是`fulfilled`状态。此时数组里的`Promise`返回
  值会组成一个数组，传递给新的`Promise`实例的回调函数。
- 数组里只要有一个`Promise`实例为`redected`状态，返回的新的`Promise`状态也是`rejected`状态。此时第一个`rejected`状态的实
  例的返回值，会传递给新的`Promise`实例的回调函数。

```js
// 假设 p1,p2,p3 都是 Promise
var p = Promise.all([p1.resolve(), p2.reject(), p3]) // p 的 状态为 rejected
```

### Promise.prototype.race()

6. 方法同样是将多个`Promise`实例，包装成一个新的`Promise`实例。参数是一个数组，数组的元素为`Promise`实例。

- 只要数组中一个`Promise`实例的状态率先改变为`fulfilled`，新的`Promise`实例的状态就跟着改变。那个率先改变的 `Promise` 实
  例的返回值，就传递给新的`Promise`的回调函数。
- 如果数组中`Promise`实例的状态都为`rejected`，那么将会将所有的`Promise`的返回值组成一个数组，传递给新的`Promise`实例的回调函数。

## 4. Promise 注意事项

1. 当 `Promise` 实例后的 `then` 方法填入了两个函数作为参数，后面又链式调用了 `Promise` 的 `catch` 方法，`catch` 方法也填入了一个函数作为参数。那么`then`方法的第二个函数参数与 `catch` 方法的函数参数都是在 `Promise` 对象状态为 `rejected` 时调用，这种情况下在 `rejected` 状态会优先调用 `then` 方法的第二个函数参数，不会调用`catch` 的函数参数。如果 `then` 方法没有第二个函数参数，那么才会调用 `catch` 的函数参数。

```js
let promise = new Promise(function (resolve, reject) {
  reject('error')
})

promise
  .then(
    (val) => {
      console.log(val, 'then')
    },
    (val) => {
      console.log(val, 'then')
    }
  )
  .catch((err) => {
    console.log(err，'catch')
  })
// 'error' 'then'

promise
  .then(
    (val) => {
      console.log(val, 'then')
    }
  )
  .catch((err) => {
    console.log(err, 'catch')
  })
// 'error' 'catch'
```

2. `Promise`构造函数的回调函数中的参数--`reject`方法可以将`promise`实例的状态改成`rejected`，等同于抛出错误。如果 `Promise` 状态已经变成 `resolved`,再抛出错误是无效的。

```js
const promise = new Promise(function (resolve, reject) {
  reject(new Error('test'))
}).catch(function (error) {
  console.log(error) // 打印抛出的错误
})

const promise = new Promise(function (resolve, reject) {
  try {
    throw new Error('test')
  } catch (e) {
    reject(e)
  }
}).catch(function (error) {
  console.log(error) // 打印抛出的错误
})

const promise = new Promise(function (resolve, reject) {
  resolve('ok')
  throw new Error('test')
})
  .then(function (value) {
    console.log(value)
  })
  .catch(function (error) {
    console.log(error)
  }) // ok
/* Promise 状态已经变成resolved,再抛出错误,不会被捕获,等于没有抛出.
   因为 Promise 的状态一旦改变,就永久保持该状态,不会再变了. */
```

3. `Promise`对象的错误具有冒泡性质，会一直向后传递，直到被捕获为止。也就是说，错误总是会被下一个`catch`语句捕获。

```js
const promise = new Promise(function (resolve, reject) {
  resolve('success')
})
promise
  .then(function (value) {
    console.log(value)
    return 'success2'
  })
  .then(function (value) {
    console.log(value)
    throw Error('error')
  })
  .catch(function (error) {
    console.log(error)
  })
/* success
     success2
     Error: error */
// 上面 3 个 Promise 对象,任何一个抛出错误都会被 catch 捕捉
```

4. `Promise` 对象的返回值一般是 `resolve` 函数或者 `reject` 函数的参数，返回值会被实例后 `then` 方法的函数参数或者 `catch` 方法的函数参数作为函数的参数接收过来。

- 一般情况下 `reject` 函数的参数通常是 `Error` 对象的实例。
- `resolve` 函数的参数除了正常的值以外，还可能是另一个 `Promise` 实例。就是所谓的 `Promise` 对象返回一个 `Promise` 对象。

```js
let promise1 = new Promise(function (resolve, reject) {})

let promise2 = new Promise((resolve, reject) => {
  resolve(promise1)
})
```

- 当 `resolve` 函数的参数是一个 `promise` 对象时, 那它本身的 `Promise` 对象的状态就失效了,它的状态是由 `resolve` 函数里的参数 -- `Promise` 对象的状态决定的.

```js
let promise1 = new Promise(function (resolve, reject) {
  reject('error')
})

let promise2 = new Promise((resolve, reject) => {
  resolve(promise1)
})

promise2
  .then(val => {
    console.log(val, 'resolve')
  })
  .catch(err => {
    console.log(err, 'reject')
  })
// error reject
/* 当 promise1 的状态是 pending 时,promise2 的状态也是 
   pending 就不会调用 then 函数和 catch 函数 */
```

5.  一般来说，不要在`then()`方法里面定义 `rejected` 状态的回调函数(即 then 的第二个参数)，而是使用`catch`方法捕获`then`方法执行中的错误，也更接近同步的写法`(try/catch)`。

- 没有使用`catch`方法指定错误处理的回调函数，`Promise` 对象抛出的错误不会传递到外层代码，即不会有任何反应。
- 当 `then` 里的回调函数返回的不是一个 `Promise`(或者说不是一个 `pending` 或者 `rejected` 状态的 `Promise`),那么不管它返回的是 `resolved` 状态的 `Promise` 或者是其他数值或者字符串, `then` 返回的 `Promise` 对象的状态一定是 `resolved`。

```js
let promise = new Promise(function (resolve, reject) {
  setTimeout(() => {
    reject('promise-error')
  }, 3000)
})

promise
  .then(
    val => {
      console.log(val, 'resolved')
      return 'SUCCESS'
    },
    val => {
      console.log(val, 'rejected')
      return 'ERROR'
    }
  )
  .then(
    val => {
      console.log(val, 'success')
    },
    val => {
      console.log(val, 'erroe')
    }
  )
/* 三秒后显示
    promise-error rejected
    ERROR success
    虽然 promise1的状态是 rejected,但是 then 返回的 
    Promise 实例的状态是 resolved */

promise
  .then(
    val => {
      console.log(val, 'resolved')
      return 'SUCCESS'
    },
    val => {
      console.log(val, 'rejected')
      return promise
    }
  )
  .then(
    val => {
      console.log(val, 'success')
    },
    val => {
      console.log(val, 'erroe')
    }
  )

/* 三秒后显示
     promise-error rejected
     promise-error erroe */
```
